<?xml version="1.0"?>
<robot name="robot_dog">
  <!-- MIT Mini Cheetah inspired structure. Each leg: thigh, calf, foot. Realistic mass, inertia, friction, damping. -->
  <!-- Body -->
  <link name="body">
    <visual>
      <origin xyz="0 0 0.25"/>
      <geometry>
        <box size="0.5 0.2 0.1"/>
      </geometry>
      <material name="gray">
        <color rgba="0.7 0.7 0.7 1"/>
      </material>
    </visual>
    <collision>
      <origin xyz="0 0 0.25"/>
      <geometry>
        <box size="0.5 0.2 0.1"/>
      </geometry>
    </collision>
    <inertial>
      <mass value="1.2"/>
      <inertia ixx="0.03" ixy="0.0" ixz="0.0" iyy="0.03" iyz="0.0" izz="0.03"/>
    </inertial>
  </link>
  <!-- Four legs: each has thigh and calf -->
  <!-- Front Left Leg -->
  <joint name="front_left_hip" type="revolute">
    <dynamics damping="0.05" friction="0.1"/>
    <parent link="body"/>
    <child link="front_left_thigh"/>
    <origin xyz="0.2 0.1 0.25"/>
    <axis xyz="0 1 0"/>
    <limit lower="-1.2" upper="1.2" effort="6" velocity="1.5"/>
  </joint>
  <link name="front_left_thigh">
    <visual>
      <origin xyz="0 0 -0.15"/>
      <geometry>
        <box size="0.06 0.06 0.3"/>
      </geometry>
      <material name="blue">
        <color rgba="0.2 0.2 0.8 1"/>
      </material>
    </visual>
    <collision>
      <origin xyz="0 0 -0.15"/>
      <geometry>
        <box size="0.06 0.06 0.3"/>
      </geometry>
    </collision>
    <inertial>
      <mass value="0.25"/>
      <inertia ixx="0.002" ixy="0.0" ixz="0.0" iyy="0.002" iyz="0.0" izz="0.002"/>
    </inertial>
  </link>
  <joint name="front_left_knee" type="revolute">
    <dynamics damping="0.05" friction="0.1"/>
    <parent link="front_left_thigh"/>
    <child link="front_left_calf"/>
    <origin xyz="0 0 -0.3"/>
    <axis xyz="0 1 0"/>
    <limit lower="-1.2" upper="1.2" effort="6" velocity="1.5"/>
  </joint>
  <link name="front_left_calf">
    <visual>
      <origin xyz="0 0 -0.15"/>
      <geometry>
        <box size="0.04 0.04 0.3"/>
      </geometry>
      <material name="red">
        <color rgba="0.8 0.2 0.2 1"/>
      </material>
    </visual>
    <collision>
      <origin xyz="0 0 -0.15"/>
      <geometry>
        <box size="0.04 0.04 0.3"/>
      </geometry>
    </collision>
    <inertial>
      <mass value="0.15"/>
      <inertia ixx="0.001" ixy="0.0" ixz="0.0" iyy="0.001" iyz="0.0" izz="0.001"/>
    </inertial>
  </link>
  <!-- Front Right Leg -->
  <joint name="front_right_hip" type="revolute">
    <dynamics damping="0.05" friction="0.1"/>
    <parent link="body"/>
    <child link="front_right_thigh"/>
    <origin xyz="0.2 -0.1 0.25"/>
    <axis xyz="0 1 0"/>
    <limit lower="-1.2" upper="1.2" effort="6" velocity="1.5"/>
  </joint>
  <link name="front_right_thigh">
    <visual>
      <origin xyz="0 0 -0.15"/>
      <geometry>
        <box size="0.06 0.06 0.3"/>
      </geometry>
      <material name="blue"/>
    </visual>
    <collision>
      <origin xyz="0 0 -0.15"/>
      <geometry>
        <box size="0.06 0.06 0.3"/>
      </geometry>
    </collision>
    <inertial>
      <mass value="0.25"/>
      <inertia ixx="0.002" ixy="0.0" ixz="0.0" iyy="0.002" iyz="0.0" izz="0.002"/>
    </inertial>
  </link>
  <joint name="front_right_knee" type="revolute">
    <dynamics damping="0.05" friction="0.1"/>
    <parent link="front_right_thigh"/>
    <child link="front_right_calf"/>
    <origin xyz="0 0 -0.3"/>
    <axis xyz="0 1 0"/>
    <limit lower="-1.2" upper="1.2" effort="6" velocity="1.5"/>
  </joint>
  <link name="front_right_calf">
    <visual>
      <origin xyz="0 0 -0.15"/>
      <geometry>
        <box size="0.04 0.04 0.3"/>
      </geometry>
      <material name="red"/>
    </visual>
    <collision>
      <origin xyz="0 0 -0.15"/>
      <geometry>
        <box size="0.04 0.04 0.3"/>
      </geometry>
    </collision>
    <inertial>
      <mass value="0.15"/>
      <inertia ixx="0.001" ixy="0.0" ixz="0.0" iyy="0.001" iyz="0.0" izz="0.001"/>
    </inertial>
  </link>
  <!-- Back Left Leg -->
  <joint name="back_left_hip" type="revolute">
    <dynamics damping="0.05" friction="0.1"/>
    <parent link="body"/>
    <child link="back_left_thigh"/>
    <origin xyz="-0.2 0.1 0.25"/>
    <axis xyz="0 1 0"/>
    <limit lower="-1.2" upper="1.2" effort="6" velocity="1.5"/>
  </joint>
  <link name="back_left_thigh">
    <visual>
      <origin xyz="0 0 -0.15"/>
      <geometry>
        <box size="0.06 0.06 0.3"/>
      </geometry>
      <material name="blue"/>
    </visual>
    <collision>
      <origin xyz="0 0 -0.15"/>
      <geometry>
        <box size="0.06 0.06 0.3"/>
      </geometry>
    </collision>
    <inertial>
      <mass value="0.25"/>
      <inertia ixx="0.002" ixy="0.0" ixz="0.0" iyy="0.002" iyz="0.0" izz="0.002"/>
    </inertial>
  </link>
  <joint name="back_left_knee" type="revolute">
    <dynamics damping="0.05" friction="0.1"/>
    <parent link="back_left_thigh"/>
    <child link="back_left_calf"/>
    <origin xyz="0 0 -0.3"/>
    <axis xyz="0 1 0"/>
    <limit lower="-1.2" upper="1.2" effort="6" velocity="1.5"/>
  </joint>
  <link name="back_left_calf">
    <visual>
      <origin xyz="0 0 -0.15"/>
      <geometry>
        <box size="0.04 0.04 0.3"/>
      </geometry>
      <material name="red"/>
    </visual>
    <collision>
      <origin xyz="0 0 -0.15"/>
      <geometry>
        <box size="0.04 0.04 0.3"/>
      </geometry>
    </collision>
    <inertial>
      <mass value="0.15"/>
      <inertia ixx="0.001" ixy="0.0" ixz="0.0" iyy="0.001" iyz="0.0" izz="0.001"/>
    </inertial>
  </link>
  <!-- Back Right Leg -->
  <joint name="back_right_hip" type="revolute">
    <dynamics damping="0.05" friction="0.1"/>
    <parent link="body"/>
    <child link="back_right_thigh"/>
    <origin xyz="-0.2 -0.1 0.25"/>
    <axis xyz="0 1 0"/>
    <limit lower="-1.2" upper="1.2" effort="6" velocity="1.5"/>
  </joint>
  <link name="back_right_thigh">
    <visual>
      <origin xyz="0 0 -0.15"/>
      <geometry>
        <box size="0.06 0.06 0.3"/>
      </geometry>
      <material name="blue"/>
    </visual>
    <collision>
      <origin xyz="0 0 -0.15"/>
      <geometry>
        <box size="0.06 0.06 0.3"/>
      </geometry>
    </collision>
    <inertial>
      <mass value="0.25"/>
      <inertia ixx="0.002" ixy="0.0" ixz="0.0" iyy="0.002" iyz="0.0" izz="0.002"/>
    </inertial>
  </link>
  <joint name="back_right_knee" type="revolute">
    <dynamics damping="0.05" friction="0.1"/>
    <parent link="back_right_thigh"/>
    <child link="back_right_calf"/>
    <origin xyz="0 0 -0.3"/>
    <axis xyz="0 1 0"/>
    <limit lower="-1.2" upper="1.2" effort="6" velocity="1.5"/>
  </joint>
  <link name="back_right_calf">
    <visual>
      <origin xyz="0 0 -0.15"/>
      <geometry>
        <box size="0.04 0.04 0.3"/>
      </geometry>
      <material name="red"/>
    </visual>
    <collision>
      <origin xyz="0 0 -0.15"/>
      <geometry>
        <box size="0.04 0.04 0.3"/>
      </geometry>
    </collision>
    <inertial>
      <mass value="0.15"/>
      <inertia ixx="0.001" ixy="0.0" ixz="0.0" iyy="0.001" iyz="0.0" izz="0.001"/>
    </inertial>
  </link>
</robot>
